<?xml version="1.0" encoding="utf-8" ?>
<robot name="fsrobo_r">
    <material name="black">
        <color rgba="0.0 0.0 0.0 1.0" />
    </material>
    <material name="blue">
        <color rgba="0.0 0.0 0.8 1.0" />
    </material>
    <material name="green">
        <color rgba="0.0 0.8 0.0 1.0" />
    </material>
    <material name="grey">
        <color rgba="0.2 0.2 0.2 1.0" />
    </material>
    <material name="orange">
        <color rgba="1.0 0.423529411765 0.0392156862745 1.0" />
    </material>
    <material name="brown">
        <color rgba="0.870588235294 0.811764705882 0.764705882353 1.0" />
    </material>
    <material name="red">
        <color rgba="0.8 0.0 0.0 1.0" />
    </material>
    <material name="white">
        <color rgba="1.0 1.0 1.0 1.0" />
    </material>
    <link name="base_link">
        <inertial>
            <origin xyz="6.20129635789006E-06 0.00135671010372665 0.00692741827175326" rpy="0 0 0" />
            <mass value="0.224918104064038" />
            <inertia ixx="0.000389773121010351" ixy="5.34979023842647E-08" ixz="2.00299715681034E-09" iyy="0.000393784206533644" iyz="1.8618345474573E-06" izz="0.000763322543979528" />
        </inertial>
        <visual>
            <origin xyz="0 0 0" rpy="0 0 0" />
            <geometry>
                <mesh filename="package://i611_ros/models/i611/meshes/base_link.STL" />
            </geometry>
            <material name="">
                <color rgba="0.792156862745098 0.819607843137255 0.933333333333333 1" />
            </material>
        </visual>
        <collision>
            <origin xyz="0 0 0" rpy="0 0 0" />
            <geometry>
                <mesh filename="package://i611_ros/models/i611/meshes/base_link.STL" />
            </geometry>
        </collision>
    </link>
    <link name="Link1">
        <inertial>
            <origin xyz="-0.00449037408423813 5.42440907528791E-06 0.0715874027691071" rpy="0 0 0" />
            <mass value="1.1964979585014" />
            <inertia ixx="0.00235325407469509" ixy="-1.48424194830244E-07" ixz="0.00016645431594179" iyy="0.00238080305757056" iyz="-3.71645517568927E-07" izz="0.00214862307498412" />
        </inertial>
        <visual>
            <origin xyz="0 0 0" rpy="0 0 0" />
            <geometry>
                <mesh filename="package://i611_ros/models/i611/meshes/Link1.STL" />
            </geometry>
            <material name="">
                <color rgba="0.792156862745098 0.819607843137255 0.933333333333333 1" />
            </material>
        </visual>
        <collision>
            <origin xyz="0 0 0" rpy="0 0 0" />
            <geometry>
                <mesh filename="package://i611_ros/models/i611/meshes/Link1.STL" />
            </geometry>
        </collision>
    </link>
    <joint name="Joint1" type="revolute">
        <origin xyz="0 0 0" rpy="0 0 0" />
        <parent link="base_link" />
        <child link="Link1" />
        <axis xyz="0 0 1" />
        <limit lower="-4.1888" upper="4.1888" effort="0" velocity="3.11049" />
    </joint>
    <link name="Link2">
        <inertial>
            <origin xyz="-0.126463562505262 -3.03757464646919E-14 0.189799410965193" rpy="0 0 0" />
            <mass value="3.71491032829736" />
            <inertia ixx="0.0996449226656911" ixy="-4.07081213433656E-15" ixz="0.000531355089159735" iyy="0.100320218055197" iyz="-2.73732399977317E-06" izz="0.00607078426291308" />
        </inertial>
        <visual>
            <origin xyz="0 0 0" rpy="0 0 0" />
            <geometry>
                <mesh filename="package://i611_ros/models/i611/meshes/Link2_nsr1105n.stl" />
            </geometry>
            <material name="">
                <color rgba="0.792156862745098 0.819607843137255 0.933333333333333 1" />
            </material>
        </visual>
        <collision>
            <origin xyz="0 0 0" rpy="0 0 0" />
            <geometry>
                <mesh filename="package://i611_ros/models/i611/meshes/Link2_nsr1105n.stl" />
            </geometry>
        </collision>
    </link>
    <joint name="Joint2" type="revolute">
        <origin xyz="0 0 0.0875" rpy="0 0 0" />
        <parent link="Link1" />
        <child link="Link2" />
        <axis xyz="1 0 0" />
        <limit lower="-4.1888" upper="4.1888" effort="0" velocity="3.11049" />
    </joint>
    <link name="Link3">
        <inertial>
            <origin xyz="-0.0181715886077434 -8.39942636869206E-06 0.00361736607529833" rpy="0 0 0" />
            <mass value="0.503493344111679" />
            <inertia ixx="0.000606835380422718" ixy="2.96258447607099E-07" ixz="-6.8421095589689E-05" iyy="0.000746558385545657" iyz="-2.34699770879584E-08" izz="0.000681452998524084" />
        </inertial>
        <visual>
            <origin xyz="0 0 0" rpy="0 0 0" />
            <geometry>
                <mesh filename="package://i611_ros/models/i611/meshes/Link3.STL" />
            </geometry>
            <material name="">
                <color rgba="0.792156862745098 0.819607843137255 0.933333333333333 1" />
            </material>
        </visual>
        <collision>
            <origin xyz="0 0 0" rpy="0 0 0" />
            <geometry>
                <mesh filename="package://i611_ros/models/i611/meshes/Link3.STL" />
            </geometry>
        </collision>
    </link>
    <joint name="Joint3" type="revolute">
        <origin xyz="0 0 0.420" rpy="0 0 0" />
        <parent link="Link2" />
        <child link="Link3" />
        <axis xyz="1 0 0" />
        <limit lower="-4.1888" upper="4.1888" effort="0" velocity="3.11049" />
    </joint>
    <link name="Link4">
        <inertial>
            <origin xyz="0.00290243681192058 4.92118154597773E-06 -0.0738374738187304" rpy="0 0 0" />
            <mass value="0.835817436377135" />
            <inertia ixx="0.0051838603413169" ixy="4.30855334856876E-08" ixz="-0.000214303665531665" iyy="0.00526559628549006" iyz="-4.86165136068341E-07" izz="0.000590028561985229" />
        </inertial>
        <visual>
            <origin xyz="0 0 0" rpy="0 0 0" />
            <geometry>
                <mesh filename="package://i611_ros/models/i611/meshes/Link4_nsr1105n.stl" />
            </geometry>
            <material name="">
                <color rgba="0.792156862745098 0.819607843137255 0.933333333333333 1" />
            </material>
        </visual>
        <collision>
            <origin xyz="0 0 0" rpy="0 0 0" />
            <geometry>
                <mesh filename="package://i611_ros/models/i611/meshes/Link4_nsr1105n.stl" />
            </geometry>
        </collision>
    </link>
    <joint name="Joint4" type="revolute">
        <origin xyz="0 0 0.440" rpy="0 0 0" />
        <parent link="Link3" />
        <child link="Link4" />
        <axis xyz="0 0 1" />
        <limit lower="-4.1888" upper="4.1888" effort="0" velocity="3.11049" />
    </joint>
    <link name="Link5">
        <inertial>
            <origin xyz="-0.00762763949469519 -1.06459091140225E-05 0.00458167547641364" rpy="0 0 0" />
            <mass value="0.397519557815901" />
            <inertia ixx="0.00038454224185" ixy="2.51938979759281E-07" ixz="-4.92173834393031E-05" iyy="0.000421678593966681" iyz="-2.77663008675825E-08" izz="0.000358331267792745" />
        </inertial>
        <visual>
            <origin xyz="0 0 0" rpy="0 0 0" />
            <geometry>
                <mesh filename="package://i611_ros/models/i611/meshes/Link5.STL" />
            </geometry>
            <material name="">
                <color rgba="0.792156862745098 0.819607843137255 0.933333333333333 1" />
            </material>
        </visual>
        <collision>
            <origin xyz="0 0 0" rpy="0 0 0" />
            <geometry>
                <mesh filename="package://i611_ros/models/i611/meshes/Link5.STL" />
            </geometry>
        </collision>
    </link>
    <joint name="Joint5" type="revolute">
        <origin xyz="0.1003 0 0" rpy="0 0 0" />
        <parent link="Link4" />
        <child link="Link5" />
        <axis xyz="1 0 0" />
        <limit lower="-4.1888" upper="4.1888" effort="0" velocity="3.11049" />
    </joint>
    <link name="Link6">
        <inertial>
            <origin xyz="0.001824741161344 -1.2714577393637E-05 -0.0183104466551915" rpy="0 0 0" />
            <mass value="0.0659925254230773" />
            <inertia ixx="3.46638767440248E-05" ixy="-3.0599679783686E-08" ixz="-5.91110846528508E-07" iyy="4.40852639111946E-05" iyz="4.19435440614541E-09" izz="6.53486052794694E-05" />
        </inertial>
        <visual>
            <origin xyz="0 0 0" rpy="0 0 0" />
            <geometry>
                <mesh filename="package://i611_ros/models/i611/meshes/Link6.STL" />
            </geometry>
            <material name="">
                <color rgba="0.792156862745098 0.819607843137255 0.933333333333333 1" />
            </material>
        </visual>
        <collision>
            <origin xyz="0 0 0" rpy="0 0 0" />
            <geometry>
                <mesh filename="package://i611_ros/models/i611/meshes/Link6.STL" />
            </geometry>
        </collision>
    </link>
    <joint name="Joint6" type="revolute">
        <origin xyz="0 0 0.085" rpy="0 0 -1.5707" />
        <parent link="Link5" />
        <child link="Link6" />
        <axis xyz="0 0 1" />
        <limit lower="-6.2832" upper="6.2832" effort="0" velocity="3.11049" />
    </joint>
    <joint name="arm_fixed1" type="fixed">
        <origin rpy="0 0 0" xyz="0 0 0" />
        <parent link="Link6" />
        <child link="hand_base" />
    </joint>
    <link name="hand_base">
        <collision>
            <origin rpy="0 0 0" xyz="0 0 0.0175" />
            <geometry>
                <box size="0.08 0.05 0.035" />
            </geometry>
        </collision>
        <visual>
            <origin rpy="0 0 0" xyz="0 0 0.0175" />
            <geometry>
                <box size="0.08 0.05 0.035" />
            </geometry>
        </visual>
        <inertial>
            <mass value="0.1" />
            <origin xyz="0 0 0" rpy="0 0 0" />
            <inertia ixx="0.03" iyy="0.03" izz="0.03" ixy="0.0" ixz="0.0" iyz="0.0" />
        </inertial>
    </link>
    <joint name="arm_fixed2" type="fixed">
        <origin rpy="0 0 0" xyz="0 0 0" />
        <parent link="hand_base" />
        <child link="rh_p12_rn_base" />
    </joint>
    <!-- base -->
    <link name="rh_p12_rn_base">
        <collision>
            <origin rpy="0 0 0" xyz="0 0 0.035" />
            <geometry>
                <mesh filename="package://i611_ros/models/i611/meshes/base.stl" scale="0.001 0.001 0.001" />
            </geometry>
        </collision>
        <visual>
            <origin rpy="0 0 0" xyz="0 0 0.035" />
            <geometry>
                <mesh filename="package://i611_ros/models/i611/meshes/base.stl" scale="0.001 0.001 0.001" />
            </geometry>
            <material name="grey" />
        </visual>
        <inertial>
            <origin rpy="0 0 0" xyz="0.000 0.000 0.067" />
            <mass value="0.236" />
            <!--<inertia ixx="0.00017" ixy="0.0" ixz="0.0" iyy="0.00011" iyz="0.0" izz="0.00017" />-->
            <inertia ixx="1.0" ixy="0.0" ixz="0.0" iyy="1.0" iyz="0.0" izz="1.0" />
        </inertial>
    </link>
    <!-- Joint -->
    <joint name="rh_p12_rn" type="revolute">
        <parent link="rh_p12_rn_base" />
        <child link="rh_p12_rn_r1" />
        <origin rpy="0 0 0" xyz="0.0 0.008 0.083" />
        <axis xyz="1 0 0" />
        <limit effort="1000" lower="0.0" upper="1.1" velocity="6.5" />
        <dynamics damping="0.7" />
    </joint>
    <!-- rh_p12_rn_r1 -->
    <link name="rh_p12_rn_r1">
        <collision>
            <origin rpy="0 0 0" xyz="0 0 0" />
            <geometry>
                <mesh filename="package://i611_ros/models/i611/meshes/r1.stl" scale="0.001 0.001 0.001" />
            </geometry>
        </collision>
        <visual>
            <origin rpy="0 0 0" xyz="0 0 0" />
            <geometry>
                <mesh filename="package://i611_ros/models/i611/meshes/r1.stl" scale="0.001 0.001 0.001" />
            </geometry>
            <material name="grey" />
        </visual>
        <inertial>
            <origin rpy="0 0 0" xyz="0.000 0.034 0.004" />
            <mass value="0.068" />
            <!--<inertia ixx="0.00004" ixy="0.0" ixz="0.0" iyy="0.00002" iyz="-0.00001" izz="0.00002" />-->
            <inertia ixx="1.0" ixy="0.0" ixz="0.0" iyy="1.0" iyz="0.0" izz="1.0" />
        </inertial>
    </link>
    <!-- Right Joint 2 -->
    <joint name="rh_r2" type="revolute">
        <parent link="rh_p12_rn_r1" />
        <child link="rh_p12_rn_r2" />
        <origin rpy="0 0 0" xyz="0.0 0.0493634 0.0285" />
        <axis xyz="-1 0 0" />
        <limit effort="1000" lower="0.0" upper="1.0" velocity="6.5" />
        <dynamics damping="0.7" />
    </joint>
    <!-- rh_p12_rn_r2 -->
    <link name="rh_p12_rn_r2">
        <collision>
            <origin rpy="0 0 0" xyz="0 0 0" />
            <geometry>
                <mesh filename="package://i611_ros/models/i611/meshes/r2.stl" scale="0.001 0.001 0.001" />
            </geometry>
        </collision>
        <visual>
            <origin rpy="0 0 0" xyz="0 0 0" />
            <geometry>
                <mesh filename="package://i611_ros/models/i611/meshes/r2.stl" scale="0.001 0.001 0.001" />
            </geometry>
            <material name="grey" />
        </visual>
        <inertial>
            <origin rpy="0 0 0" xyz="0.000 0.006 0.011" />
            <mass value="0.022" />
            <!--<inertia ixx="0.0" ixy="0.0" ixz="0.0" iyy="0.00001" iyz="0.0" izz="0.0" />-->
            <inertia ixx="1.0" ixy="0.0" ixz="0.0" iyy="1.0" iyz="0.0" izz="1.0" />
        </inertial>
    </link>
    <!-- Left Joint 1 -->
    <joint name="rh_l1" type="revolute">
        <parent link="rh_p12_rn_base" />
        <child link="rh_p12_rn_l1" />
        <origin rpy="0 0 0" xyz="0.0 -0.008 0.083" />
        <axis xyz="-1 0 0" />
        <limit effort="1000" lower="0.0" upper="1.1" velocity="6.5" />
        <dynamics damping="0.7" />
    </joint>
    <!-- rh_p12_rn_l1 -->
    <link name="rh_p12_rn_l1">
        <collision>
            <origin rpy="0 0 0" xyz="0 0 0" />
            <geometry>
                <mesh filename="package://i611_ros/models/i611/meshes/l1.stl" scale="0.001 0.001 0.001" />
            </geometry>
        </collision>
        <visual>
            <origin rpy="0 0 0" xyz="0 0 0" />
            <geometry>
                <mesh filename="package://i611_ros/models/i611/meshes/l1.stl" scale="0.001 0.001 0.001" />
            </geometry>
            <material name="grey" />
        </visual>
        <inertial>
            <origin rpy="0 0 0" xyz="0.000 -0.034 0.004" />
            <mass value="0.068" />
            <!--<inertia ixx="0.00004" ixy="0.0" ixz="0.0" iyy="0.00002" iyz="0.00001" izz="0.00002" />-->
            <inertia ixx="1.0" ixy="0.0" ixz="0.0" iyy="1.0" iyz="0.0" izz="1.0" />
        </inertial>
    </link>
    <!-- Left Joint 2 -->
    <joint name="rh_l2" type="revolute">
        <parent link="rh_p12_rn_l1" />
        <child link="rh_p12_rn_l2" />
        <origin rpy="0 0 0" xyz="0.0 -0.0493634 0.0285" />
        <axis xyz="1 0 0" />
        <limit effort="1000" lower="0.0" upper="1.0" velocity="6.5" />
        <dynamics damping="0.7" />
    </joint>
    <!-- rh_p12_rn_l2 -->
    <link name="rh_p12_rn_l2">
        <collision>
            <origin rpy="0 0 0" xyz="0 0 0" />
            <geometry>
                <mesh filename="package://i611_ros/models/i611/meshes/l2.stl" scale="0.001 0.001 0.001" />
            </geometry>
        </collision>
        <visual>
            <origin rpy="0 0 0" xyz="0 0 0" />
            <geometry>
                <mesh filename="package://i611_ros/models/i611/meshes/l2.stl" scale="0.001 0.001 0.001" />
            </geometry>
            <material name="grey" />
        </visual>
        <inertial>
            <origin rpy="0 0 0" xyz="0.000 -0.006 0.011" />
            <mass value="0.022" />
            <!--<inertia ixx="0.0" ixy="0.0" ixz="0.0" iyy="0.00001" iyz="0.0" izz="0.0" />-->
            <inertia ixx="1.0" ixy="0.0" ixz="0.0" iyy="1.0" iyz="0.0" izz="1.0" />
        </inertial>
    </link>
    <transmission name="trans_Joint1">
        <type>transmission_interface/SimpleTransmission</type>
        <joint name="Joint1">
            <hardwareInterface>hardware_interface/EffortJointInterface</hardwareInterface>
        </joint>
        <actuator name="Joint1_motor">
            <hardwareInterface>hardware_interface/EffortJointInterface</hardwareInterface>
            <mechanicalReduction>1</mechanicalReduction>
        </actuator>
    </transmission>
    <transmission name="trans_Joint2">
        <type>transmission_interface/SimpleTransmission</type>
        <joint name="Joint2">
            <hardwareInterface>hardware_interface/EffortJointInterface</hardwareInterface>
        </joint>
        <actuator name="Joint2_motor">
            <hardwareInterface>hardware_interface/EffortJointInterface</hardwareInterface>
            <mechanicalReduction>1</mechanicalReduction>
        </actuator>
    </transmission>
    <transmission name="trans_Joint3">
        <type>transmission_interface/SimpleTransmission</type>
        <joint name="Joint3">
            <hardwareInterface>hardware_interface/EffortJointInterface</hardwareInterface>
        </joint>
        <actuator name="Joint3_motor">
            <hardwareInterface>hardware_interface/EffortJointInterface</hardwareInterface>
            <mechanicalReduction>1</mechanicalReduction>
        </actuator>
    </transmission>
    <transmission name="trans_Joint4">
        <type>transmission_interface/SimpleTransmission</type>
        <joint name="Joint4">
            <hardwareInterface>hardware_interface/EffortJointInterface</hardwareInterface>
        </joint>
        <actuator name="Joint4_motor">
            <hardwareInterface>hardware_interface/EffortJointInterface</hardwareInterface>
            <mechanicalReduction>1</mechanicalReduction>
        </actuator>
    </transmission>
    <transmission name="trans_Joint5">
        <type>transmission_interface/SimpleTransmission</type>
        <joint name="Joint5">
            <hardwareInterface>hardware_interface/EffortJointInterface</hardwareInterface>
        </joint>
        <actuator name="Joint5_motor">
            <hardwareInterface>hardware_interface/EffortJointInterface</hardwareInterface>
            <mechanicalReduction>1</mechanicalReduction>
        </actuator>
    </transmission>
    <transmission name="trans_Joint6">
        <type>transmission_interface/SimpleTransmission</type>
        <joint name="Joint6">
            <hardwareInterface>hardware_interface/EffortJointInterface</hardwareInterface>
        </joint>
        <actuator name="Joint6_motor">
            <hardwareInterface>hardware_interface/EffortJointInterface</hardwareInterface>
            <mechanicalReduction>1</mechanicalReduction>
        </actuator>
    </transmission>
    <transmission name="trans_rh_p12_rn">
        <type>transmission_interface/SimpleTransmission</type>
        <joint name="rh_p12_rn">
            <hardwareInterface>hardware_interface/EffortJointInterface</hardwareInterface>
        </joint>
        <actuator name="rh_p12_rn_motor">
            <hardwareInterface>hardware_interface/EffortJointInterface</hardwareInterface>
            <mechanicalReduction>1</mechanicalReduction>
        </actuator>
    </transmission>
    <transmission name="trans_rh_r2">
        <type>transmission_interface/SimpleTransmission</type>
        <joint name="rh_r2">
            <hardwareInterface>hardware_interface/EffortJointInterface</hardwareInterface>
        </joint>
        <actuator name="rh_r2_motor">
            <hardwareInterface>hardware_interface/EffortJointInterface</hardwareInterface>
            <mechanicalReduction>1</mechanicalReduction>
        </actuator>
    </transmission>
    <transmission name="trans_rh_l1">
        <type>transmission_interface/SimpleTransmission</type>
        <joint name="rh_l1">
            <hardwareInterface>hardware_interface/EffortJointInterface</hardwareInterface>
        </joint>
        <actuator name="rh_l1_motor">
            <hardwareInterface>hardware_interface/EffortJointInterface</hardwareInterface>
            <mechanicalReduction>1</mechanicalReduction>
        </actuator>
    </transmission>
    <transmission name="trans_rh_l2">
        <type>transmission_interface/SimpleTransmission</type>
        <joint name="rh_l2">
            <hardwareInterface>hardware_interface/EffortJointInterface</hardwareInterface>
        </joint>
        <actuator name="rh_l2_motor">
            <hardwareInterface>hardware_interface/EffortJointInterface</hardwareInterface>
            <mechanicalReduction>1</mechanicalReduction>
        </actuator>
    </transmission>
    <gazebo>
        <plugin name="gazebo_ros_control" filename="libgazebo_ros_control.so">
            <robotNamespace>/</robotNamespace>
        </plugin>
    </gazebo>
</robot>

